Workbook

Sheet Resumen mensual
A1: Mes | B1: Ingresos (€) | C1: Gastos de vida (€) | D1: Pagos fijos (€) | E1: Pagos aplazables (€) | F1: Pagos amigos (€) | G1: Total pagos deuda (€) | H1: Ahorro del mes (€) | I1: Saldo a fin de mes (€)
A2: 46296 | B2: =SUMIFS(Calendario!$F$3:$F$72,Calendario!$D$3:$D$72,"Ingreso",Calendario!$B$3:$B$72,A2) | C2: =-SUMIFS(Calendario!$F$3:$F$72,Calendario!$D$3:$D$72,"Gasto",Calendario!$B$3:$B$72,A2) | D2: =-SUMIFS(Calendario!$F$3:$F$72,Calendario!$D$3:$D$72,"Fijo",Calendario!$B$3:$B$72,A2) | E2: =-SUMIFS(Calendario!$F$3:$F$72,Calendario!$D$3:$D$72,"Aplazable",Calendario!$B$3:$B$72,A2) | F2: =-SUMIFS(Calendario!$F$3:$F$72,Calendario!$D$3:$D$72,"Amigo",Calendario!$B$3:$B$72,A2) | G2: =D2+E2+F2 | H2: =B2-C2-G2 | I2: =Supuestos!$B$5+SUM($H$2:H2)
A3: 46327 | B3: =SUMIFS(Calendario!$F$3:$F$72,Calendario!$D$3:$D$72,"Ingreso",Calendario!$B$3:$B$72,A3) | C3: =-SUMIFS(Calendario!$F$3:$F$72,Calendario!$D$3:$D$72,"Gasto",Calendario!$B$3:$B$72,A3) | D3: =-SUMIFS(Calendario!$F$3:$F$72,Calendario!$D$3:$D$72,"Fijo",Calendario!$B$3:$B$72,A3) | E3: =-SUMIFS(Calendario!$F$3:$F$72,Calendario!$D$3:$D$72,"Aplazable",Calendario!$B$3:$B$72,A3) | F3: =-SUMIFS(Calendario!$F$3:$F$72,Calendario!$D$3:$D$72,"Amigo",Calendario!$B$3:$B$72,A3) | G3: =D3+E3+F3 | H3: =B3-C3-G3 | I3: =Supuestos!$B$5+SUM($H$2:H3)
A4: 46357 | B4: =SUMIFS(Calendario!$F$3:$F$72,Calendario!$D$3:$D$72,"Ingreso",Calendario!$B$3:$B$72,A4) | C4: =-SUMIFS(Calendario!$F$3:$F$72,Calendario!$D$3:$D$72,"Gasto",Calendario!$B$3:$B$72,A4) | D4: =-SUMIFS(Calendario!$F$3:$F$72,Calendario!$D$3:$D$72,"Fijo",Calendario!$B$3:$B$72,A4) | E4: =-SUMIFS(Calendario!$F$3:$F$72,Calendario!$D$3:$D$72,"Aplazable",Calendario!$B$3:$B$72,A4) | F4: =-SUMIFS(Calendario!$F$3:$F$72,Calendario!$D$3:$D$72,"Amigo",Calendario!$B$3:$B$72,A4) | G4: =D4+E4+F4 | H4: =B4-C4-G4 | I4: =Supuestos!$B$5+SUM($H$2:H4)
A5: 46388 | B5: =SUMIFS(Calendario!$F$3:$F$72,Calendario!$D$3:$D$72,"Ingreso",Calendario!$B$3:$B$72,A5) | C5: =-SUMIFS(Calendario!$F$3:$F$72,Calendario!$D$3:$D$72,"Gasto",Calendario!$B$3:$B$72,A5) | D5: =-SUMIFS(Calendario!$F$3:$F$72,Calendario!$D$3:$D$72,"Fijo",Calendario!$B$3:$B$72,A5) | E5: =-SUMIFS(Calendario!$F$3:$F$72,Calendario!$D$3:$D$72,"Aplazable",Calendario!$B$3:$B$72,A5) | F5: =-SUMIFS(Calendario!$F$3:$F$72,Calendario!$D$3:$D$72,"Amigo",Calendario!$B$3:$B$72,A5) | G5: =D5+E5+F5 | H5: =B5-C5-G5 | I5: =Supuestos!$B$5+SUM($H$2:H5)
A6: 46419 | B6: =SUMIFS(Calendario!$F$3:$F$72,Calendario!$D$3:$D$72,"Ingreso",Calendario!$B$3:$B$72,A6) | C6: =-SUMIFS(Calendario!$F$3:$F$72,Calendario!$D$3:$D$72,"Gasto",Calendario!$B$3:$B$72,A6) | D6: =-SUMIFS(Calendario!$F$3:$F$72,Calendario!$D$3:$D$72,"Fijo",Calendario!$B$3:$B$72,A6) | E6: =-SUMIFS(Calendario!$F$3:$F$72,Calendario!$D$3:$D$72,"Aplazable",Calendario!$B$3:$B$72,A6) | F6: =-SUMIFS(Calendario!$F$3:$F$72,Calendario!$D$3:$D$72,"Amigo",Calendario!$B$3:$B$72,A6) | G6: =D6+E6+F6 | H6: =B6-C6-G6 | I6: =Supuestos!$B$5+SUM($H$2:H6)
A7: 46447 | B7: =SUMIFS(Calendario!$F$3:$F$72,Calendario!$D$3:$D$72,"Ingreso",Calendario!$B$3:$B$72,A7) | C7: =-SUMIFS(Calendario!$F$3:$F$72,Calendario!$D$3:$D$72,"Gasto",Calendario!$B$3:$B$72,A7) | D7: =-SUMIFS(Calendario!$F$3:$F$72,Calendario!$D$3:$D$72,"Fijo",Calendario!$B$3:$B$72,A7) | E7: =-SUMIFS(Calendario!$F$3:$F$72,Calendario!$D$3:$D$72,"Aplazable",Calendario!$B$3:$B$72,A7) | F7: =-SUMIFS(Calendario!$F$3:$F$72,Calendario!$D$3:$D$72,"Amigo",Calendario!$B$3:$B$72,A7) | G7: =D7+E7+F7 | H7: =B7-C7-G7 | I7: =Supuestos!$B$5+SUM($H$2:H7)
A8: 46478 | B8: =SUMIFS(Calendario!$F$3:$F$72,Calendario!$D$3:$D$72,"Ingreso",Calendario!$B$3:$B$72,A8) | C8: =-SUMIFS(Calendario!$F$3:$F$72,Calendario!$D$3:$D$72,"Gasto",Calendario!$B$3:$B$72,A8) | D8: =-SUMIFS(Calendario!$F$3:$F$72,Calendario!$D$3:$D$72,"Fijo",Calendario!$B$3:$B$72,A8) | E8: =-SUMIFS(Calendario!$F$3:$F$72,Calendario!$D$3:$D$72,"Aplazable",Calendario!$B$3:$B$72,A8) | F8: =-SUMIFS(Calendario!$F$3:$F$72,Calendario!$D$3:$D$72,"Amigo",Calendario!$B$3:$B$72,A8) | G8: =D8+E8+F8 | H8: =B8-C8-G8 | I8: =Supuestos!$B$5+SUM($H$2:H8)
A9: 46508 | B9: =SUMIFS(Calendario!$F$3:$F$72,Calendario!$D$3:$D$72,"Ingreso",Calendario!$B$3:$B$72,A9) | C9: =-SUMIFS(Calendario!$F$3:$F$72,Calendario!$D$3:$D$72,"Gasto",Calendario!$B$3:$B$72,A9) | D9: =-SUMIFS(Calendario!$F$3:$F$72,Calendario!$D$3:$D$72,"Fijo",Calendario!$B$3:$B$72,A9) | E9: =-SUMIFS(Calendario!$F$3:$F$72,Calendario!$D$3:$D$72,"Aplazable",Calendario!$B$3:$B$72,A9) | F9: =-SUMIFS(Calendario!$F$3:$F$72,Calendario!$D$3:$D$72,"Amigo",Calendario!$B$3:$B$72,A9) | G9: =D9+E9+F9 | H9: =B9-C9-G9 | I9: =Supuestos!$B$5+SUM($H$2:H9)
A10: 46539 | B10: =SUMIFS(Calendario!$F$3:$F$72,Calendario!$D$3:$D$72,"Ingreso",Calendario!$B$3:$B$72,A10) | C10: =-SUMIFS(Calendario!$F$3:$F$72,Calendario!$D$3:$D$72,"Gasto",Calendario!$B$3:$B$72,A10) | D10: =-SUMIFS(Calendario!$F$3:$F$72,Calendario!$D$3:$D$72,"Fijo",Calendario!$B$3:$B$72,A10) | E10: =-SUMIFS(Calendario!$F$3:$F$72,Calendario!$D$3:$D$72,"Aplazable",Calendario!$B$3:$B$72,A10) | F10: =-SUMIFS(Calendario!$F$3:$F$72,Calendario!$D$3:$D$72,"Amigo",Calendario!$B$3:$B$72,A10) | G10: =D10+E10+F10 | H10: =B10-C10-G10 | I10: =Supuestos!$B$5+SUM($H$2:H10)
A11: 46569 | B11: =SUMIFS(Calendario!$F$3:$F$72,Calendario!$D$3:$D$72,"Ingreso",Calendario!$B$3:$B$72,A11) | C11: =-SUMIFS(Calendario!$F$3:$F$72,Calendario!$D$3:$D$72,"Gasto",Calendario!$B$3:$B$72,A11) | D11: =-SUMIFS(Calendario!$F$3:$F$72,Calendario!$D$3:$D$72,"Fijo",Calendario!$B$3:$B$72,A11) | E11: =-SUMIFS(Calendario!$F$3:$F$72,Calendario!$D$3:$D$72,"Aplazable",Calendario!$B$3:$B$72,A11) | F11: =-SUMIFS(Calendario!$F$3:$F$72,Calendario!$D$3:$D$72,"Amigo",Calendario!$B$3:$B$72,A11) | G11: =D11+E11+F11 | H11: =B11-C11-G11 | I11: =Supuestos!$B$5+SUM($H$2:H11)
A12: 46600 | B12: =SUMIFS(Calendario!$F$3:$F$72,Calendario!$D$3:$D$72,"Ingreso",Calendario!$B$3:$B$72,A12) | C12: =-SUMIFS(Calendario!$F$3:$F$72,Calendario!$D$3:$D$72,"Gasto",Calendario!$B$3:$B$72,A12) | D12: =-SUMIFS(Calendario!$F$3:$F$72,Calendario!$D$3:$D$72,"Fijo",Calendario!$B$3:$B$72,A12) | E12: =-SUMIFS(Calendario!$F$3:$F$72,Calendario!$D$3:$D$72,"Aplazable",Calendario!$B$3:$B$72,A12) | F12: =-SUMIFS(Calendario!$F$3:$F$72,Calendario!$D$3:$D$72,"Amigo",Calendario!$B$3:$B$72,A12) | G12: =D12+E12+F12 | H12: =B12-C12-G12 | I12: =Supuestos!$B$5+SUM($H$2:H12)
A13: 46631 | B13: =SUMIFS(Calendario!$F$3:$F$72,Calendario!$D$3:$D$72,"Ingreso",Calendario!$B$3:$B$72,A13) | C13: =-SUMIFS(Calendario!$F$3:$F$72,Calendario!$D$3:$D$72,"Gasto",Calendario!$B$3:$B$72,A13) | D13: =-SUMIFS(Calendario!$F$3:$F$72,Calendario!$D$3:$D$72,"Fijo",Calendario!$B$3:$B$72,A13) | E13: =-SUMIFS(Calendario!$F$3:$F$72,Calendario!$D$3:$D$72,"Aplazable",Calendario!$B$3:$B$72,A13) | F13: =-SUMIFS(Calendario!$F$3:$F$72,Calendario!$D$3:$D$72,"Amigo",Calendario!$B$3:$B$72,A13) | G13: =D13+E13+F13 | H13: =B13-C13-G13 | I13: =Supuestos!$B$5+SUM($H$2:H13)
A14: 46661 | B14: =SUMIFS(Calendario!$F$3:$F$72,Calendario!$D$3:$D$72,"Ingreso",Calendario!$B$3:$B$72,A14) | C14: =-SUMIFS(Calendario!$F$3:$F$72,Calendario!$D$3:$D$72,"Gasto",Calendario!$B$3:$B$72,A14) | D14: =-SUMIFS(Calendario!$F$3:$F$72,Calendario!$D$3:$D$72,"Fijo",Calendario!$B$3:$B$72,A14) | E14: =-SUMIFS(Calendario!$F$3:$F$72,Calendario!$D$3:$D$72,"Aplazable",Calendario!$B$3:$B$72,A14) | F14: =-SUMIFS(Calendario!$F$3:$F$72,Calendario!$D$3:$D$72,"Amigo",Calendario!$B$3:$B$72,A14) | G14: =D14+E14+F14 | H14: =B14-C14-G14 | I14: =Supuestos!$B$5+SUM($H$2:H14)
A15: TOTAL | B15: =SUM(B2:B14) | C15: =SUM(C2:C14) | D15: =SUM(D2:D14) | E15: =SUM(E2:E14) | F15: =SUM(F2:F14) | G15: =SUM(G2:G14) | H15: =SUM(H2:H14)
A17: Saldo más bajo del plan | C17: =MIN(Calendario!G2:G72)
A18: Fecha del saldo más bajo | C18: =INDEX(Calendario!A2:A72,MATCH(C17,Calendario!G2:G72,0))

Sheet Deudas
A1: Deuda | B1: Bloque | C1: Entidad / persona | D1: Importe a devolver (€) | E1: Pagado en el plan (€) | F1: Queda (€) | G1: Último pago | H1: Condiciones | I1: Ahorro por liquidar (€)
A2: Moneyman | B2: Fijo | C2: Moneyman | D2: 1400 | E2: =-SUMIFS(Calendario!$F$3:$F$72,Calendario!$E$3:$E$72,A2) | F2: =D2-E2-I2 | G2: =_xlfn.MAXIFS(Calendario!$A$3:$A$72,Calendario!$E$3:$E$72,A2) | H2: Pago único el 1 nov, sin volver a pedirlo. Te dieron 1.100 € | I2: 0
A3: Vivus | B3: Fijo | C3: Vivus | D3: 2148 | E3: =-SUMIFS(Calendario!$F$3:$F$72,Calendario!$E$3:$E$72,A3) | F3: =D3-E3-I3 | G3: =_xlfn.MAXIFS(Calendario!$A$3:$A$72,Calendario!$E$3:$E$72,A3) | H3: 4 × 537 €, no aplazable. Plan: cuota del 1 nov y liquidar el resto el 29 nov (total 1.500 €) | I3: 648
A4: Smartcredito | B4: Fijo | C4: Smartcredito | D4: 435 | E4: =-SUMIFS(Calendario!$F$3:$F$72,Calendario!$E$3:$E$72,A4) | F4: =D4-E4-I4 | G4: =_xlfn.MAXIFS(Calendario!$A$3:$A$72,Calendario!$E$3:$E$72,A4) | H4: Pago único el 14 nov. Volver a pedirlo cuesta: recibes 300 €, devuelves 435 € | I4: 0
A5: Santander (préstamo) | B5: Fijo | C5: Santander | D5: 1994.93 | E5: =-SUMIFS(Calendario!$F$3:$F$72,Calendario!$E$3:$E$72,A5) | F5: =D5-E5-I5 | G5: =_xlfn.MAXIFS(Calendario!$A$3:$A$72,Calendario!$E$3:$E$72,A5) | H5: 96 €/mes; desde mar 2027 dentro de los 500 €/mes | I5: 0
A6: Pagolisto 1 | B6: Aplazable | C6: Pagolisto *6284 | D6: 693.34 | E6: =-SUMIFS(Calendario!$F$3:$F$72,Calendario!$E$3:$E$72,A6) | F6: =D6-E6-I6 | G6: =_xlfn.MAXIFS(Calendario!$A$3:$A$72,Calendario!$E$3:$E$72,A6) | H6: Aplazable: en nov pagas la cuota y la vuelves a pedir sin intereses; 3 cuotas dic–feb | I6: 0
A7: Pagolisto 2 | B7: Aplazable | C7: Pagolisto *6727 | D7: 923.61 | E7: =-SUMIFS(Calendario!$F$3:$F$72,Calendario!$E$3:$E$72,A7) | F7: =D7-E7-I7 | G7: =_xlfn.MAXIFS(Calendario!$A$3:$A$72,Calendario!$E$3:$E$72,A7) | H7: Aplazable: en nov pagas la cuota y la vuelves a pedir sin intereses; 3 cuotas dic–feb | I7: 0
A8: Crédito Santander 1 | B8: Aplazable | C8: Santander *0773 | D8: 1483.63 | E8: =-SUMIFS(Calendario!$F$3:$F$72,Calendario!$E$3:$E$72,A8) | F8: =D8-E8-I8 | G8: =_xlfn.MAXIFS(Calendario!$A$3:$A$72,Calendario!$E$3:$E$72,A8) | H8: Aplazable: en nov pagas la cuota y la vuelves a pedir sin intereses; 3 cuotas dic–feb | I8: 0
A9: Crédito Santander 2 | B9: Aplazable | C9: Santander *4475 | D9: 2326.76 | E9: =-SUMIFS(Calendario!$F$3:$F$72,Calendario!$E$3:$E$72,A9) | F9: =D9-E9-I9 | G9: =_xlfn.MAXIFS(Calendario!$A$3:$A$72,Calendario!$E$3:$E$72,A9) | H9: 122,46 €/mes; desde mar 2027 dentro de los 500 €/mes | I9: 0
A10: Ama | B10: Amigo | C10: Ama | D10: 600 | E10: =-SUMIFS(Calendario!$F$3:$F$72,Calendario!$E$3:$E$72,A10) | F10: =D10-E10-I10 | G10: =_xlfn.MAXIFS(Calendario!$A$3:$A$72,Calendario!$E$3:$E$72,A10) | H10: Prioridad: 29 nov, con la nómina | I10: 0
A11: Joserra | B11: Amigo | C11: Joserra | D11: 400 | E11: =-SUMIFS(Calendario!$F$3:$F$72,Calendario!$E$3:$E$72,A11) | F11: =D11-E11-I11 | G11: =_xlfn.MAXIFS(Calendario!$A$3:$A$72,Calendario!$E$3:$E$72,A11) | H11: Sin plazo ni interés. Se devuelve antes de fin de año | I11: 0
A12: Xabi | B12: Amigo | C12: Xabi | D12: 300 | E12: =-SUMIFS(Calendario!$F$3:$F$72,Calendario!$E$3:$E$72,A12) | F12: =D12-E12-I12 | G12: =_xlfn.MAXIFS(Calendario!$A$3:$A$72,Calendario!$E$3:$E$72,A12) | H12: Sin plazo ni interés | I12: 0
A13: Sergio | B13: Amigo | C13: Sergio | D13: 1700 | E13: =-SUMIFS(Calendario!$F$3:$F$72,Calendario!$E$3:$E$72,A13) | F13: =D13-E13-I13 | G13: =_xlfn.MAXIFS(Calendario!$A$3:$A$72,Calendario!$E$3:$E$72,A13) | H13: Sin plazo ni interés | I13: 0
A14: Txomin | B14: Amigo | C14: Txomin | D14: 2500 | E14: =-SUMIFS(Calendario!$F$3:$F$72,Calendario!$E$3:$E$72,A14) | F14: =D14-E14-I14 | G14: =_xlfn.MAXIFS(Calendario!$A$3:$A$72,Calendario!$E$3:$E$72,A14) | H14: Sin plazo ni interés | I14: 0
A15: TOTAL | D15: =SUM(D2:D14) | E15: =SUM(E2:E14) | F15: =SUM(F2:F14) | G15: =MAX(G2:G14) | H15: ← libre de deudas | I15: =SUM(I2:I14)
A17: Por bloque
A18: Fijo | D18: =SUMIFS(D2:D14,B2:B14,A18)
A19: Aplazable | D19: =SUMIFS(D2:D14,B2:B14,A19)
A20: Amigo | D20: =SUMIFS(D2:D14,B2:B14,A20)

Sheet Calendario
A1: Fecha | B1: Mes | C1: Concepto | D1: Tipo | E1: Deuda | F1: Importe (€) | G1: Saldo (€) | I1: Leyenda
A2: =Supuestos!B4 | B2: =DATE(YEAR(A2),MONTH(A2),1) | C2: Saldo inicial | G2: =Supuestos!B5 | I2: Fijo | J2: No se aplaza
A3: 46309 | B3: =DATE(YEAR(A3),MONTH(A3),1) | C3: Gastos de vida hasta el 29 oct (estimado) | D3: Gasto | F3: =-Supuestos!B6 | G3: =G2+F3 | I3: Aplazable | J3: Aplazable sin coste
A4: 46324 | B4: =DATE(YEAR(A4),MONTH(A4),1) | C4: Nómina | D4: Ingreso | F4: 3100 | G4: =G3+F4 | I4: Amigo | J4: Préstamo personal
A5: 46327 | B5: =DATE(YEAR(A5),MONTH(A5),1) | C5: Moneyman · pago (sin volver a pedirlo) | D5: Fijo | E5: Moneyman | F5: -1400 | G5: =G4+F5 | I5: Ingreso | J5: Nómina / extras
A6: 46327 | B6: =DATE(YEAR(A6),MONTH(A6),1) | C6: Vivus · cuota 1/4 (no aplazable) | D6: Fijo | E6: Vivus | F6: -537 | G6: =G5+F6 | I6: Gasto | J6: Gastos de vida
A7: 46327 | B7: =DATE(YEAR(A7),MONTH(A7),1) | C7: Pagolisto 1 · pagas 231,11 € y lo vuelves a pedir (neto 0) | D7: Aplazable | F7: 0 | G7: =G6+F7
A8: 46327 | B8: =DATE(YEAR(A8),MONTH(A8),1) | C8: Pagolisto 2 · pagas 307,87 € y lo vuelves a pedir (neto 0) | D8: Aplazable | F8: 0 | G8: =G7+F8 | I8: Azul: importe fijo · Verde: viene de Supuestos
A9: 46327 | B9: =DATE(YEAR(A9),MONTH(A9),1) | C9: Crédito Santander 1 · pagas 494,54 € y lo vuelves a pedir (neto 0) | D9: Aplazable | F9: 0 | G9: =G8+F9
A10: 46327 | B10: =DATE(YEAR(A10),MONTH(A10),1) | C10: Santander (préstamo) · cuota | D10: Fijo | E10: Santander (préstamo) | F10: -96 | G10: =G9+F10
A11: 46327 | B11: =DATE(YEAR(A11),MONTH(A11),1) | C11: Crédito Santander 2 · cuota | D11: Aplazable | E11: Crédito Santander 2 | F11: -122.46 | G11: =G10+F11
A12: 46327 | B12: =DATE(YEAR(A12),MONTH(A12),1) | C12: Gastos de vida | D12: Gasto | F12: =-Supuestos!B7 | G12: =G11+F12
A13: 46340 | B13: =DATE(YEAR(A13),MONTH(A13),1) | C13: Smartcredito · pago único | D13: Fijo | E13: Smartcredito | F13: -435 | G13: =G12+F13
A14: 46355 | B14: =DATE(YEAR(A14),MONTH(A14),1) | C14: Nómina | D14: Ingreso | F14: 3453.01 | G14: =G13+F14
A15: 46355 | B15: =DATE(YEAR(A15),MONTH(A15),1) | C15: Vivus · liquidación del resto (total 1.500 € en vez de 2.148 €) | D15: Fijo | E15: Vivus | F15: -963 | G15: =G14+F15
A16: 46355 | B16: =DATE(YEAR(A16),MONTH(A16),1) | C16: Devolución a Ama | D16: Amigo | E16: Ama | F16: -600 | G16: =G15+F16
A17: 46357 | B17: =DATE(YEAR(A17),MONTH(A17),1) | C17: Santander (préstamo) · cuota | D17: Fijo | E17: Santander (préstamo) | F17: -96 | G17: =G16+F17
A18: 46357 | B18: =DATE(YEAR(A18),MONTH(A18),1) | C18: Crédito Santander 2 · cuota | D18: Aplazable | E18: Crédito Santander 2 | F18: -122.46 | G18: =G17+F18
A19: 46357 | B19: =DATE(YEAR(A19),MONTH(A19),1) | C19: Pagolisto 1 · cuota 1/3 | D19: Aplazable | E19: Pagolisto 1 | F19: -231.11 | G19: =G18+F19
A20: 46357 | B20: =DATE(YEAR(A20),MONTH(A20),1) | C20: Pagolisto 2 · cuota 1/3 | D20: Aplazable | E20: Pagolisto 2 | F20: -307.87 | G20: =G19+F20
A21: 46357 | B21: =DATE(YEAR(A21),MONTH(A21),1) | C21: Crédito Santander 1 · cuota 1/3 | D21: Aplazable | E21: Crédito Santander 1 | F21: -494.54 | G21: =G20+F21
A22: 46357 | B22: =DATE(YEAR(A22),MONTH(A22),1) | C22: Gastos de vida | D22: Gasto | F22: =-Supuestos!B7 | G22: =G21+F22
A23: 46385 | B23: =DATE(YEAR(A23),MONTH(A23),1) | C23: Nómina | D23: Ingreso | F23: 3453.01 | G23: =G22+F23
A24: 46385 | B24: =DATE(YEAR(A24),MONTH(A24),1) | C24: Paga extra de diciembre | D24: Ingreso | F24: 2014.69 | G24: =G23+F24
A25: 46385 | B25: =DATE(YEAR(A25),MONTH(A25),1) | C25: Devolución a Joserra | D25: Amigo | E25: Joserra | F25: -400 | G25: =G24+F25
A26: 46388 | B26: =DATE(YEAR(A26),MONTH(A26),1) | C26: Santander (préstamo) · cuota | D26: Fijo | E26: Santander (préstamo) | F26: -96 | G26: =G25+F26
A27: 46388 | B27: =DATE(YEAR(A27),MONTH(A27),1) | C27: Crédito Santander 2 · cuota | D27: Aplazable | E27: Crédito Santander 2 | F27: -122.46 | G27: =G26+F27
A28: 46388 | B28: =DATE(YEAR(A28),MONTH(A28),1) | C28: Pagolisto 1 · cuota 2/3 | D28: Aplazable | E28: Pagolisto 1 | F28: -231.11 | G28: =G27+F28
A29: 46388 | B29: =DATE(YEAR(A29),MONTH(A29),1) | C29: Pagolisto 2 · cuota 2/3 | D29: Aplazable | E29: Pagolisto 2 | F29: -307.87 | G29: =G28+F29
A30: 46388 | B30: =DATE(YEAR(A30),MONTH(A30),1) | C30: Crédito Santander 1 · cuota 2/3 | D30: Aplazable | E30: Crédito Santander 1 | F30: -494.54 | G30: =G29+F30
A31: 46388 | B31: =DATE(YEAR(A31),MONTH(A31),1) | C31: Devolución a Xabi | D31: Amigo | E31: Xabi | F31: -300 | G31: =G30+F31
A32: 46388 | B32: =DATE(YEAR(A32),MONTH(A32),1) | C32: Gastos de vida | D32: Gasto | F32: =-Supuestos!B7 | G32: =G31+F32
A33: 46416 | B33: =DATE(YEAR(A33),MONTH(A33),1) | C33: Nómina | D33: Ingreso | F33: 3173.56 | G33: =G32+F33
A34: 46419 | B34: =DATE(YEAR(A34),MONTH(A34),1) | C34: Santander (préstamo) · cuota | D34: Fijo | E34: Santander (préstamo) | F34: -96 | G34: =G33+F34
A35: 46419 | B35: =DATE(YEAR(A35),MONTH(A35),1) | C35: Crédito Santander 2 · cuota | D35: Aplazable | E35: Crédito Santander 2 | F35: -122.46 | G35: =G34+F35
A36: 46419 | B36: =DATE(YEAR(A36),MONTH(A36),1) | C36: Pagolisto 1 · cuota 3/3 | D36: Aplazable | E36: Pagolisto 1 | F36: -231.12 | G36: =G35+F36
A37: 46419 | B37: =DATE(YEAR(A37),MONTH(A37),1) | C37: Pagolisto 2 · cuota 3/3 | D37: Aplazable | E37: Pagolisto 2 | F37: -307.87 | G37: =G36+F37
A38: 46419 | B38: =DATE(YEAR(A38),MONTH(A38),1) | C38: Crédito Santander 1 · cuota 3/3 | D38: Aplazable | E38: Crédito Santander 1 | F38: -494.55 | G38: =G37+F38
A39: 46419 | B39: =DATE(YEAR(A39),MONTH(A39),1) | C39: Devolución a Sergio | D39: Amigo | E39: Sergio | F39: -1700 | G39: =G38+F39
A40: 46419 | B40: =DATE(YEAR(A40),MONTH(A40),1) | C40: Gastos de vida | D40: Gasto | F40: =-Supuestos!B7 | G40: =G39+F40
...

Sheet Supuestos
A1: Plan de pagos de deudas
A2: Las celdas amarillas con texto azul son datos editables: el resto del libro se recalcula.
A4: Fecha de partida | B4: 46312 | C4: Último saldo comunicado
A5: Saldo inicial (€) | B5: 600 | C5: Saldo en cuenta el 17 oct 2026, según el usuario
A6: Gastos de vida hasta el 29 oct (€) | B6: 300 | C6: Estimación. Con más de ~350 € el 1 dic queda en negativo (salvo que aplaces los aplazables ese mes)
A7: Gastos de vida mensuales desde nov (€) | B7: 700 | C7: Indicado por el usuario
A8: Pago mensual al bloque Santander desde mar 2027 (€) | B8: 500 | C8: Indicado por el usuario (fijo en el calendario)
A10: Nóminas, pagas extra y variable: netas, según la previsión del desplazamiento (octubre: 3.100 €, confirmado por el usuario).
A11: Deudas sin intereses salvo Moneyman (recibes 1.100 €, devuelves 1.400 €).
A12: Aplazables (se pagan y se vuelven a pedir sin intereses): Pagolisto 1 y 2, Crédito Santander 1 y 2. No aplazables: Santander (préstamo), Moneyman, Vivus y Smartcredito.
A13: Escenario: nómina de octubre de 3.100 €, Smartcredito el 14 nov, sin préstamos puente ni volver a pedir Moneyman. Ama el 29 nov, Vivus liquidado el 29 nov.
